<?xml version="1.0" encoding="UTF-8"?>
<robot name="car" xmlns:xacro="http://www.ros.org/wiki/xacro">
    <!-- Robot type parameter -->
    <xacro:arg name="robot_type" default="track_car"/>
    
    <!-- Materials -->
    <material name="yellow">
        <color rgba="1 1 0 1"/>
    </material>
    
    <material name="green">
        <color rgba="0 1 0 1"/>
    </material>

    <material name="black">
        <color rgba="0 0 0 1"/>
    </material>

    <!-- Main body link -->
    <link name="base_link">
        <inertial>
            <mass value="1.0"/>
            <origin xyz="0 0 0" rpy="0 0 0"/>
            <inertia ixx="0.0395" ixy="0" ixz="0" iyy="0.086" iyz="0" izz="0.0125"/>
        </inertial>
        <visual>
            <geometry>
                <box size="0.5 0.3 0.1"/>
            </geometry>
            <xacro:if value="${'$(arg robot_type)' == 'track_car'}">
                <material name="yellow"/>
            </xacro:if>
            <xacro:if value="${'$(arg robot_type)' == 'target_car'}">
                <material name="green"/>
            </xacro:if>
        </visual>
        <collision>
            <geometry>
                <box size="0.5 0.3 0.1"/>
            </geometry>
        </collision>
        <!-- ...existing code... -->
    </link>

    <!-- Wheel joint -->
    <joint name="wheel_1_joint" type="continuous">
        <parent link="base_link"/>
        <child link="wheel_1"/>
        <!-- ...existing code... -->
    </joint>
    
    <!-- Wheel link -->
    <link name="wheel_1">
        <inertial>
            <mass value="0.1"/>
            <origin xyz="0 0 0" rpy="0 0 0"/>
            <inertia ixx="0.000375" ixy="0" ixz="0" iyy="0.000375" iyz="0" izz="0.00072"/>
        </inertial>
        <visual>
            <geometry>
                <cylinder radius="0.06" length="0.04"/>
            </geometry>
            <material name="black"/>
        </visual>
        <collision>
            <geometry>
                <cylinder radius="0.06" length="0.04"/>
            </geometry>
        </collision>
        <!-- ...existing code... -->
    </link>
    
    <!-- 添加右轮关节 -->
    <joint name="wheel_2_joint" type="continuous">
        <parent link="base_link"/>
        <child link="wheel_2"/>
        <origin xyz="0 -0.15 -0.05" rpy="0 0 0"/>
        <axis xyz="0 1 0"/>
    </joint>
    
    <!-- 添加右轮连杆 -->
    <link name="wheel_2">
        <inertial>
            <mass value="0.1"/>
            <origin xyz="0 0 0" rpy="0 0 0"/>
            <inertia ixx="0.000375" ixy="0" ixz="0" iyy="0.000375" iyz="0" izz="0.00072"/>
        </inertial>
        <visual>
            <geometry>
                <cylinder radius="0.06" length="0.04"/>
            </geometry>
            <material name="black"/>
        </visual>
        <collision>
            <geometry>
                <cylinder radius="0.06" length="0.04"/>
            </geometry>
        </collision>
    </link>

    <!-- Other wheels are also green -->
    <!-- ...existing code... -->

    <!-- Camera link -->
    <link name="camera_link">
        <visual>
            <geometry>
                <box size="0.05 0.05 0.05"/>
            </geometry>
            <material name="black"/>
        </visual>
    </link>

    <!-- Camera joint -->
    <joint name="camera_joint" type="fixed">
        <parent link="base_link"/>
        <child link="camera_link"/>
        <origin xyz="0.2 0 0.1" rpy="0 0 0"/>
    </joint>

    <!-- Camera plugin -->
    <gazebo reference="camera_link">
        <sensor type="camera" name="camera">
            <update_rate>30.0</update_rate>
            <camera name="head">
                <horizontal_fov>1.3962634</horizontal_fov>
                <image>
                    <width>640</width>
                    <height>480</height>
                    <format>R8G8B8</format>
                </image>
                <clip>
                    <near>0.02</near>
                    <far>300</far>
                </clip>
            </camera>
            <plugin name="camera_controller" filename="libgazebo_ros_camera.so">
                <alwaysOn>true</alwaysOn>
                <updateRate>0.0</updateRate>
                <cameraName>track_car/camera</cameraName>
                <imageTopicName>image_raw</imageTopicName>
                <cameraInfoTopicName>camera_info</cameraInfoTopicName>
                <frameName>camera_link</frameName>
            </plugin>
        </sensor>
    </gazebo>

    <!-- Add Gazebo plugins for differential drive -->
    <gazebo>
        <plugin name="differential_drive_controller" filename="libgazebo_ros_diff_drive.so">
            <leftJoint>wheel_1_joint</leftJoint>
            <rightJoint>wheel_2_joint</rightJoint>
            <robotNamespace>$(arg robot_type)</robotNamespace>
            <wheelSeparation>0.3</wheelSeparation>
            <wheelDiameter>0.12</wheelDiameter>
            <commandTopic>cmd_vel</commandTopic>
            <odometryTopic>odom</odometryTopic>
            <odometryFrame>odom</odometryFrame>
            <robotBaseFrame>base_link</robotBaseFrame>
            <publishWheelTF>false</publishWheelTF>
            <publishOdomTF>true</publishOdomTF>
            <publishWheelJointState>false</publishWheelJointState>
            <wheelAcceleration>1.0</wheelAcceleration>
            <wheelTorque>20</wheelTorque>
            <odometrySource>world</odometrySource>
            <updateRate>30</updateRate>
        </plugin>
    </gazebo>
</robot>
